Workbook

Sheet CL 2025 (Original)
A2: Financial Highlights (Unaudited) (in Canadian $ Million) | B2: 2025 | C2: 2024
A3: Summary of net earnings attributable to:
A4: Participating account | B4: 42 | C4: 107
A5: Common shareholder | B5: 2724 | C5: 3140
A6: Net earnings | B6: 2766 | C6: 3247
A8: Insurance service result | B8: 3450 | C8: 3258
A9: Net investment result | B9: 603 | C9: 1015
A10: Fee and other income | B10: 3016 | C10: 2853
A12: Total assets | B12: 505652 | C12: 461204
A13: Total assets under management or advisement | B13: 529301 | C13: 469722
A14: Total assets under administration | B14: 723435 | C14: 654853
A15: Total contractual service margin (net of reinsurance held) | B15: 13494 | C15: 13243
A17: Participating account surplus | B17: 3082 | C17: 3043
A18: Non-controlling interests | B18: – | C18: 10
A19: Shareholders’ equity | B19: 20938 | C19: 20909
A20: Total equity | B20: 24020 | C20: 23962
A21: LICAT Ratio | B21: 1.28 | C21: 1.3
A24: Consolidated Statements Of Earnings (in Canadian $ Million) | B24: 2025 | C24: 2024
A25: Insurance service result
A26: Insurance revenue | B26: 22131 | C26: 21007
A27: Insurance service expenses | B27: -17002 | C27: -16165
A28: Net expense from reinsurance contracts | B28: -1679 | C28: -1584
B29: 3450 | C29: 3258
A30: Net investment result (note 6)
A31: Net investment income | B31: 5837 | C31: 5719
A32: Changes in fair value on fair value through profit or loss assets | B32: 1328 | C32: 1280
B33: 7165 | C33: 6999
A34: Net finance income (expenses) from insurance contracts | B34: -6116 | C34: -5851
A35: Net finance income (expenses) from reinsurance contracts | B35: -303 | C35: 26
A36: Changes in investment contract liabilities | B36: -143 | C36: -159
B37: 603 | C37: 1015
A38: Net investment result - insurance contracts on account of segregated fund policyholders
A39: Net investment income | B39: 5044 | C39: 6828
A40: Net finance income (expenses) from insurance contracts | B40: -5044 | C40: -6828
B41: — | C41: —
A42: Other income and expenses
A43: Fee and other income | B43: 3016 | C43: 2853
A44: Operating and administrative expenses | B44: -3408 | C44: -3088
A45: Amortization of finite life intangible assets (note 9) | B45: -194 | C45: -185
A46: Financing costs (note 19) | B46: -107 | C46: -105
...

Sheet CL 2024 (Original)
A2: Financial Highlights (in Canadian $ millions) | B2: 2024 | C2: 2023
A3: Summary of net earnings attributable to:
A4: Participating account | B4: 107 | C4: 24
A5: Common shareholder | B5: 3140 | C5: 2394
A6: Net earnings | B6: 3247 | C6: 2418
A8: Insurance service result | B8: 3258 | C8: 3002
A9: Net investment result | B9: 1015 | C9: 200
A10: Fee and other income | B10: 2853 | C10: 2163
A12: Total assets | B12: 461204 | C12: 410616
A13: Total assets under management | B13: 576201 | C13: 499941
A14: Total assets under administration | B14: 654853 | C14: 567652
A15: Total contractual service margin (net of reinsurance held) | B15: 13243 | C15: 12458
A17: Participating account surplus | B17: 3043 | C17: 2844
A18: Non-controlling interests | B18: 10 | C18: 16
... A21: LICAT Ratio | B21: 1.3 | C21: 1.28
A24: Consolidated Statements of Earnings (in Canadian $ millions) | B24: 2024 | C24: 2023
A25: Insurance service result
A26: Insurance revenue | B26: 21007 | C26: 20188
A27: Insurance service expenses | B27: -16165 | C27: -15622
A28: Net expense from reinsurance contracts | B28: -1584 | C28: -1564
B29: 3258 | C29: 3002
A30: Net investment result (note 6)
A31: Net investment income | B31: 5719 | C31: 4877
A32: Changes in fair value on fair value through profit or loss assets | B32: 1280 | C32: 4267
B33: 6999 | C33: 9144
A34: Net finance income (expenses) from insurance contracts | B34: -5851 | C34: -9032
A35: Net finance income (expenses) from reinsurance contracts | B35: 26 | C35: 266
A36: Changes in investment contract liabilities | B36: -159 | C36: -178
B37: 1015 | C37: 200
A38: Net investment result - insurance contracts on account of segregated fund policyholders
A39: Net investment income (loss) | B39: 6828 | C39: 4808
A40: Net finance income (expenses) from insurance contracts | B40: -6828 | C40: -4808
B41: — | C41: —
A42: Other income and expenses
A43: Fee and other income | B43: 2853 | C43: 2163
A44: Operating and administrative expenses | B44: -3088 | C44: -2635
A45: Amortization of finite life intangible assets (note 9) | B45: -185 | C45: -160
A46: Financing costs (note 19) | B46: -105 | C46: -105
A47: Restructuring expenses (note 4) | B47: -49 | C47: -126
A48: Earnings before income taxes | B48: 3699 | C48: 2339
...

Sheet CL 2023 (Original)
A2: Financial Highlights (unaudited) (in Canadian $ millions) | B2: 2023 | C2: 2022
A3: Summary of net earnings attributable to:
A4: Participating account | B4: 24 | C4: -91
A5: Common shareholder | B5: 2394 | C5: 3377
A6: Net earnings | B6: 2418 | C6: 3286
A8: Insurance service result | B8: 3002 | C8: 2766
A9: Net investment result | B9: 200 | C9: 1464
A10: Fee and other income | B10: 2163 | C10: 1932
A12: Total assets | B12: 410616 | C12: 378654
A13: Total assets under management | B13: 499941 | C13: 444064
A14: Total assets under administration | B14: 567652 | C14: 481753
A15: Total contractual service margin (net of reinsurance held) | B15: 12458 | C15: 12496
A17: Participating account surplus | B17: 2844 | C17: 2733
A18: Non-controlling interests | B18: 16 | C18: 51
... A20: Total equity | B20: 22673 | C20: 22788
A21: LICAT Ratio | B21: 1.28 | C21: ='CL 2022 (Original)'!B26 -> 1.2
A23: Consolidated Statements of Earnings (in Canadian $ millions) | B23: 2023 | C23: 2022
C24: (Restated)
A25: Insurance service result
A26: Insurance revenue | B26: 20188 | C26: 19424
A27: Insurance service expenses | B27: -15622 | C27: -15110
A28: Net expense from reinsurance contracts | B28: -1564 | C28: -1548
B29: 3002 | C29: 2766
A30: Net investment result (note 6)
A31: Net investment income | B31: 4877 | C31: 4599
A32: Changes in fair value on fair value through profit or loss assets | B32: 4267 | C32: -20289
B33: 9144 | C33: -15690
A34: Net finance income (expenses) from insurance contracts | B34: -9032 | C34: 18201
A35: Net finance income (expenses) from reinsurance contracts | B35: 266 | C35: -1261
A36: Changes in investment contract liabilities | B36: -178 | C36: 214
B37: 200 | C37: 1464
A38: Net investment result - insurance contracts on account of segregated fund policyholders
A39: Net investment income (loss) | B39: 4808 | C39: -4130
A40: Net finance income (expenses) from insurance contracts | B40: -4808 | C40: 4130
B41: — | C41: —
A42: Other income and expenses
A43: Fee and other income | B43: 2163 | C43: 1932
A44: Operating and administrative expenses | B44: -2635 | C44: -2221
A45: Amortization of finite life intangible assets (note 9) | B45: -160 | C45: -173
A46: Financing costs (note 19) | B46: -105 | C46: -104
...

Sheet CL 2022 (Original)
A2: Financial Highlight (unaudited) (in Canadian $ millions) | B2: 2022 | C2: 2021
A3: Summary of net earnings attribute to:
A4: Participating account
A5: Net earnings before policyholder dividend | B5: 1809 | C5: 1708
A6: Policyholder dividends | B6: 1625 | C6: 1405
A7: Net earnings – participating account | B7: 184 | C7: 303
A8: Common shareholder | B8: 2995 | C8: 2868
A9: Net earnings | B9: 3179 | C9: 3171
A11: Total net premiums | B11: 54322 | C11: 50609
A12: Total premiums and deposits | B12: 98025 | C12: 94160
A13: Fee and other income | B13: 3325 | C13: 3414
A14: Net policyholder benefits, dividends and experience refunds | B14: 48246 | C14: 42319
A15: Total assets | B15: 393982 | C15: 426404
A16: Proprietary mutual funds and institutional assets | B16: 65410 | C16: 77019
A17: Total assets under management | B17: 459392 | C17: 503423
... A26: LICAT Ratio | B26: 1.2 | C26: 1.24
A29: Consolidated Statements of Earnings (in Canadian $ millions) | B29: 2022 | C29: 2021
A30: Income
A31: Premium income
A32: Gross premiums written | B32: 58060 | C32: 54340
A33: Ceded premiums | B33: -3738 | C33: -3731
A34: Total net premiums | B34: 54322 | C34: 50609
A35: Net investment income (note 6)
A36: Regular net investment income | B36: -4898 | C36: 4502
A37: Changes in fair value through profit or loss | B37: -16011 | C37: -1240
A38: Total net investment income (loss) | B38: -11113 | C38: 3262
A39: Fee and other income | B39: -3325 | C39: 3414
B40: 46534 | C40: 57285
A41: Benefits and expenses
A42: Policyholder benefits
A43: Gross | B43: 48611 | C43: 43401
A44: Ceded | B44: -2537 | C44: -2505
A45: Total net policyholder benefits | B45: 46074 | C45: 40896
A46: Changes in insurance and investment contract liabilities
A47: Gross | B47: -12410 | C47: 4394
A48: Ceded | B48: 1169 | C48: 1081
A49: Total net changes in insurance and investment contract liabilities | B49: -11241 | C49: 5475
A50: Policyholder dividends and experience refunds | B50: 2172 | C50: 1423
A51: Total paid or credited to policyholders | B51: 37005 | C51: 47794
A52: Commissions | B52: 2148 | C52: 2107
...

Sheet CL Consolidated Summary
A1: Financial item (CAD $ millions) | B1: 2022 | C1: 2023 | D1: 2024 | E1: 2025
A2: Insurance revenue | B2: {=_xlfn.XLOOKUP(A2,CL2023_Consolidated_Statements_Of_Earnings[[#All],[Consolidated Statements of Earnings (in Canadian $ millions)]],CL2023_Consolidated_Statements_Of_Earnings[[#All],[2022]],"Not Found",0)} -> 19424 | C2: {=_xlfn.XLOOKUP(A2,CL2023_Consolidated_Statements_Of_Earnings[[#All],[Consolidated Statements of Earnings (in Canadian $ millions)]],CL2023_Consolidated_Statements_Of_Earnings[[#All],[2023]],"Not Found", 0)} -> 20188 | D2: {=_xlfn.XLOOKUP(A2,CL2024_Consolidated_Statement_Of_Earnings[[#All],[Consolidated Statements of Earnings (in Canadian $ millions)]],CL2024_Consolidated_Statement_Of_Earnings[[#All],[2024]],"Not Found", 0)} -> 21007 | E2: =_xlfn.XLOOKUP(A2,CL2025_Consolidated_Statements_Of_Earnings[Consolidated Statements Of Earnings (in Canadian $ Million)],CL2025_Consolidated_Statements_Of_Earnings[2025],"Not Found",0) -> 22131
A3: Insurance service expenses | B3: {=_xlfn.XLOOKUP(A3,CL2023_Consolidated_Statements_Of_Earnings[[#All],[Consolidated Statements of Earnings (in Canadian $ millions)]],CL2023_Consolidated_Statements_Of_Earnings[[#All],[2022]],"Not Found",0)} -> -15110 | C3: {=_xlfn.XLOOKUP(A3,CL2023_Consolidated_Statements_Of_Earnings[[#All],[Consolidated Statements of Earnings (in Canadian $ millions)]],CL2023_Consolidated_Statements_Of_Earnings[[#All],[2023]],"Not Found",0)} -> -15622 | D3: =_xlfn.XLOOKUP(A3,CL2024_Consolidated_Statement_Of_Earnings[Consolidated Statements of Earnings (in Canadian $ millions)],CL2024_Consolidated_Statement_Of_Earnings[2024],"Not Found",0) -> -16165 | E3: =_xlfn.XLOOKUP(A3,CL2025_Consolidated_Statements_Of_Earnings[Consolidated Statements Of Earnings (in Canadian $ Million)],CL2025_Consolidated_Statements_Of_Earnings[2025],"Not Found",0) -> -17002
A4: Insurance service result | B4: =SUM('CL 2023 (Original)'!C26:C28) -> 2766 | C4: =SUM('CL 2023 (Original)'!B26:B28) -> 3002 | D4: =SUM('CL 2024 (Original)'!B26:B28) -> 3258 | E4: =SUM('CL 2025 (Original)'!B26:B28) -> 3450
A5: Operating and administrative expenses | B5: {=_xlfn.XLOOKUP(A5,CL2023_Consolidated_Statements_Of_Earnings[[#All],[Consolidated Statements of Earnings (in Canadian $ millions)]],CL2023_Consolidated_Statements_Of_Earnings[[#All],[2022]],"Not Found",0)} -> -2221 | C5: {=_xlfn.XLOOKUP(A5,CL2023_Consolidated_Statements_Of_Earnings[[#All],[Consolidated Statements of Earnings (in Canadian $ millions)]],CL2023_Consolidated_Statements_Of_Earnings[[#All],[2023]],"Not Found",0)} -> -2635 | D5: {=_xlfn.XLOOKUP(A5,CL2024_Consolidated_Statement_Of_Earnings[[#All],[Consolidated Statements of Earnings (in Canadian $ millions)]],CL2024_Consolidated_Statement_Of_Earnings[[#All],[2024]],"Not Found",0)} -> -3088 | E5: {=_xlfn.XLOOKUP(A5,CL2025_Consolidated_Statements_Of_Earnings[[#All],[Consolidated Statements Of Earnings (in Canadian $ Million)]],CL2025_Consolidated_Statements_Of_Earnings[[#All],[2025]],"Not Found",0)} -> -3408
A6: Net earnings | B6: {=_xlfn.XLOOKUP(A6,CL2023_Consolidated_Statements_Of_Earnings[[#All],[Consolidated Statements of Earnings (in Canadian $ millions)]],CL2023_Consolidated_Statements_Of_Earnings[[#All],[2022]],"Not Found",0)} -> 3286 | C6: {=_xlfn.XLOOKUP(A6,CL2023_Consolidated_Statements_Of_Earnings[[#All],[Consolidated Statements of Earnings (in Canadian $ millions)]],CL2023_Consolidated_Statements_Of_Earnings[[#All],[2023]],"Not Found",0)} -> 2418 | D6: {=_xlfn.XLOOKUP(A6,CL2024_Consolidated_Statement_Of_Earnings[[#All],[Consolidated Statements of Earnings (in Canadian $ millions)]],CL2024_Consolidated_Statement_Of_Earnings[[#All],[2024]],"Not Found",0)} -> 3247 | E6: {=_xlfn.XLOOKUP(A6,CL2025_Consolidated_Statements_Of_Earnings[[#All],[Consolidated Statements Of Earnings (in Canadian $ Million)]],CL2025_Consolidated_Statements_Of_Earnings[[#All],[2025]],"Not Found",0)} -> 2766
A7: Total assets | B7: {=_xlfn.XLOOKUP(A7,CL2023_Consolidated_Balance_Sheets[[#All],[Consolidated Balance Sheets (in Canadian $ millions)]],CL2023_Consolidated_Balance_Sheets[[#All],[2022]],"Not Found", 0)} -> 378654 | C7: {=_xlfn.XLOOKUP(A7,CL2023_Consolidated_Balance_Sheets[[#All],[Consolidated Balance Sheets (in Canadian $ millions)]],CL2023_Consolidated_Balance_Sheets[[#All],[2023]],"Not Found",0)} -> 410616 | D7: {=_xlfn.XLOOKUP(A7,CL2024_Consolidated_Balance_Sheet[[#All],[Consolidated Balance Sheet (in Canadian $ millions)]],CL2024_Consolidated_Balance_Sheet[[#All],[2024]],"Not Found",0)} -> 461204 | E7: {=_xlfn.XLOOKUP(A7,CL2025_Consolidated_Balance_Sheet[[#All],[Consolidated Balance Sheet (in Canadian $ Million)]],CL2025_Consolidated_Balance_Sheet[[#All],[2025]],"Not Found",0)} -> 505652
A8: Total liabilities | B8: {=_xlfn.XLOOKUP(A8,CL2023_Consolidated_Balance_Sheets[[#All],[Consolidated Balance Sheets (in Canadian $ millions)]],CL2023_Consolidated_Balance_Sheets[[#All],[2022]],"Not Found",0)} -> 355866 | C8: {=_xlfn.XLOOKUP(A8,CL2023_Consolidated_Balance_Sheets[[#All],[Consolidated Balance Sheets (in Canadian $ millions)]],CL2023_Consolidated_Balance_Sheets[[#All],[2023]],"Not Found",0)} -> 387943 | D8: {=_xlfn.XLOOKUP(A8,CL2024_Consolidated_Balance_Sheet[[#All],[Consolidated Balance Sheet (in Canadian $ millions)]],CL2024_Consolidated_Balance_Sheet[[#All],[2024]],"Not Found",0)} -> 437242 | E8: {=_xlfn.XLOOKUP(A8,CL2025_Consolidated_Balance_Sheet[[#All],[Consolidated Balance Sheet (in Canadian $ Million)]],CL2025_Consolidated_Balance_Sheet[[#All],[2025]],"Not Found",0)} -> 481632
A9: Shareholders’ equity | B9: {=_xlfn.XLOOKUP(A9,CL2023_Financial_Highlights[[#All],[Financial Highlights (unaudited) (in Canadian $ millions)]],CL2023_Financial_Highlights[[#All],[2022]],"Not Found",0)} -> 20004 | C9: {=_xlfn.XLOOKUP(A9,CL2023_Financial_Highlights[[#All],[Financial Highlights (unaudited) (in Canadian $ millions)]],CL2023_Financial_Highlights[[#All],[2023]],"Not Found",0)} -> 19813 | D9: {=_xlfn.XLOOKUP(A9,CL2024_Financial_Highlights[[#All],[Financial Highlights (in Canadian $ millions)]],CL2024_Financial_Highlights[[#All],[2024]],"Not Found",0)} -> 20909 | E9: {=_xlfn.XLOOKUP(A9,CL2025_Financial_Highlights[[#All],[Financial Highlights (Unaudited) (in Canadian $ Million)]],CL2025_Financial_Highlights[[#All],[2025]],"Not Found",0)} -> 20938
A10: Cash and cash equivalents | B10: {=_xlfn.XLOOKUP(A10,CL2023_Consolidated_Balance_Sheets[[#All],[Consolidated Balance Sheets (in Canadian $ millions)]],CL2023_Consolidated_Balance_Sheets[[#All],[2022]],"Not Found",0)} -> 3761 | C10: {=_xlfn.XLOOKUP(A10,CL2023_Consolidated_Balance_Sheets[[#All],[Consolidated Balance Sheets (in Canadian $ millions)]],CL2023_Consolidated_Balance_Sheets[[#All],[2023]],"Not Found",0)} -> 3944 | D10: {=_xlfn.XLOOKUP(A10,CL2024_Consolidated_Balance_Sheet[[#All],[Consolidated Balance Sheet (in Canadian $ millions)]],CL2024_Consolidated_Balance_Sheet[[#All],[2024]],"Not Found",0)} -> 4522 | E10: {=_xlfn.XLOOKUP(A10,CL2025_Consolidated_Balance_Sheet[[#All],[Consolidated Balance Sheet (in Canadian $ Million)]],CL2025_Consolidated_Balance_Sheet[[#All],[2025]],"Not Found",0)} -> 4679
A11: Debentures and other debt instruments | B11: {=_xlfn.XLOOKUP(A11,CL2023_Consolidated_Balance_Sheets[[#All],[Consolidated Balance Sheets (in Canadian $ millions)]],CL2023_Consolidated_Balance_Sheets[[#All],[2022]],"Not Found",0)} -> 747 | C11: {=_xlfn.XLOOKUP(A11,CL2023_Consolidated_Balance_Sheets[[#All],[Consolidated Balance Sheets (in Canadian $ millions)]],CL2023_Consolidated_Balance_Sheets[[#All],[2023]],"Not Found",0)} -> 748 | D11: {=_xlfn.XLOOKUP(A11,CL2024_Consolidated_Balance_Sheet[[#All],[Consolidated Balance Sheet (in Canadian $ millions)]],CL2024_Consolidated_Balance_Sheet[[#All],[2024]],"Not Found",0)} -> 807 | E11: {=_xlfn.XLOOKUP(A11,CL2025_Consolidated_Balance_Sheet[[#All],[Consolidated Balance Sheet (in Canadian $ Million)]],CL2025_Consolidated_Balance_Sheet[[#All],[2025]],"Not Found",0)} -> 827
A12: Operating cash flow | B12: ='CL 2023 (Original)'!C137 -> 2343 | C12: ='CL 2023 (Original)'!B137 -> 3836 | D12: ='CL 2024 (Original)'!B132 -> 3347 | E12: ='CL 2025 (Original)'!B135 -> 3251
A13: Total contractual service margin (net of reinsurance held) | B13: {=_xlfn.XLOOKUP(A13,CL2023_Financial_Highlights[[#All],[Financial Highlights (unaudited) (in Canadian $ millions)]],CL2023_Financial_Highlights[[#All],[2022]],"Not Found",0)} -> 12496 | C13: {=_xlfn.XLOOKUP(A13,CL2023_Financial_Highlights[[#All],[Financial Highlights (unaudited) (in Canadian $ millions)]],CL2023_Financial_Highlights[[#All],[2023]],"Not Found",0)} -> 12458 | D13: {=_xlfn.XLOOKUP(A13,CL2024_Financial_Highlights[[#All],[Financial Highlights (in Canadian $ millions)]],CL2024_Financial_Highlights[[#All],[2024]],"Not Found",0)} -> 13243 | E13: {=_xlfn.XLOOKUP(A13,CL2025_Financial_Highlights[[#All],[Financial Highlights (Unaudited) (in Canadian $ Million)]],CL2025_Financial_Highlights[[#All],[2025]],"Not Found",0)} -> 13494
A14: Shareholders’ equity | B14: {=_xlfn.XLOOKUP(A14,CL2023_Financial_Highlights[[#All],[Financial Highlights (unaudited) (in Canadian $ millions)]],CL2023_Financial_Highlights[[#All],[2022]],"Not Found",0)} -> 20004 | C14: {=_xlfn.XLOOKUP(A14,CL2023_Financial_Highlights[[#All],[Financial Highlights (unaudited) (in Canadian $ millions)]],CL2023_Financial_Highlights[[#All],[2023]],"Not Found",0)} -> 19813 | D14: {=_xlfn.XLOOKUP(A14,CL2024_Financial_Highlights[[#All],[Financial Highlights (in Canadian $ millions)]],CL2024_Financial_Highlights[[#All],[2024]],"Not Found",0)} -> 20909 | E14: {=_xlfn.XLOOKUP(A14,CL2025_Financial_Highlights[[#All],[Financial Highlights (Unaudited) (in Canadian $ Million)]],CL2025_Financial_Highlights[[#All],[2025]],"Not Found",0)} -> 20938
A15: Total equity | B15: {=_xlfn.XLOOKUP(A15,CL2023_Financial_Highlights[[#All],[Financial Highlights (unaudited) (in Canadian $ millions)]],CL2023_Financial_Highlights[[#All],[2022]],"Not Found",0)} -> 22788 | C15: {=_xlfn.XLOOKUP(A15,CL2023_Financial_Highlights[[#All],[Financial Highlights (unaudited) (in Canadian $ millions)]],CL2023_Financial_Highlights[[#All],[2023]],"Not Found",0)} -> 22673 | D15: {=_xlfn.XLOOKUP(A15,CL2024_Financial_Highlights[[#All],[Financial Highlights (in Canadian $ millions)]],CL2024_Financial_Highlights[[#All],[2024]],"Not Found",0)} -> 23962 | E15: {=_xlfn.XLOOKUP(A15,CL2025_Financial_Highlights[[#All],[Financial Highlights (Unaudited) (in Canadian $ Million)]],CL2025_Financial_Highlights[[#All],[2025]],"Not Found",0)} -> 24020
A16: Dividends paid on common shares | B16: {=_xlfn.XLOOKUP(A16,CL2023_Consolidated_Statements_Of_Cash_Flows[[#All],[Consolidated Statements of Cash Flows (in Canadian $ millions)]],CL2023_Consolidated_Statements_Of_Cash_Flows[[#All],[2022]],"Not Found",0)} -> -1770 | C16: {=_xlfn.XLOOKUP(A16,CL2023_Consolidated_Statements_Of_Cash_Flows[[#All],[Consolidated Statements of Cash Flows (in Canadian $ millions)]],CL2023_Consolidated_Statements_Of_Cash_Flows[[#All],[2023]],"Not Found",0)} -> -2934 | D16: {=_xlfn.XLOOKUP(A16,CL2024_Consolidated_Statements_Of_Cash_Flow[[#All],[Consolidated Statements of Cash Flow (in Canadian $ millions)]],CL2024_Consolidated_Statements_Of_Cash_Flow[[#All],[2024]],"Not Found",0)} -> -2838 | E16: {=_xlfn.XLOOKUP(A16,CL2025_Consolidated_Statements_Of_Cash_Flow[[#All],[Consolidated Statements of Cash Flow]],CL2025_Consolidated_Statements_Of_Cash_Flow[[#All],[2025]],"Not Found",0)} -> -3150
A17: LICAT Ratio | B17: {=_xlfn.XLOOKUP(A17,CL2023_Financial_Highlights[[#All],[Financial Highlights (unaudited) (in Canadian $ millions)]],CL2023_Financial_Highlights[[#All],[2022]],"Not Found",0)} -> 1.2 | C17: {=_xlfn.XLOOKUP(A17,CL2023_Financial_Highlights[[#All],[Financial Highlights (unaudited) (in Canadian $ millions)]],CL2023_Financial_Highlights[[#All],[2023]],"Not Found",0)} -> 1.28 | D17: {=_xlfn.XLOOKUP(A17,CL2024_Financial_Highlights[[#All],[Financial Highlights (in Canadian $ millions)]],CL2024_Financial_Highlights[[#All],[2024]],"Not Found",0)} -> 1.3 | E17: {=_xlfn.XLOOKUP(A17,CL2025_Financial_Highlights[[#All],[Financial Highlights (Unaudited) (in Canadian $ Million)]],CL2025_Financial_Highlights[[#All],[2025]],"Not Found",0)} -> 1.28
